Fri Sep 13 08:43:49 MSK 2019 Thread[Thread-3,5,main] Cleanup action starting
java.sql.SQLException: Database 'C:/tmp/database' not found.
	at org.apache.derby.impl.jdbc.SQLExceptionFactory.getSQLException(Unknown Source)
	at org.apache.derby.impl.jdbc.SQLExceptionFactory.getSQLException(Unknown Source)
	at org.apache.derby.impl.jdbc.Util.generateCsSQLException(Unknown Source)
	at org.apache.derby.impl.jdbc.Util.generateCsSQLException(Unknown Source)
	at org.apache.derby.impl.jdbc.EmbedConnection.newSQLException(Unknown Source)
	at org.apache.derby.impl.jdbc.EmbedConnection.handleDBNotFound(Unknown Source)
	at org.apache.derby.impl.jdbc.EmbedConnection.<init>(Unknown Source)
	at org.apache.derby.jdbc.InternalDriver$1.run(Unknown Source)
	at org.apache.derby.jdbc.InternalDriver$1.run(Unknown Source)
	at java.security.AccessController.doPrivileged(Native Method)
	at org.apache.derby.jdbc.InternalDriver.getNewEmbedConnection(Unknown Source)
	at org.apache.derby.jdbc.InternalDriver$LoginCallable.call(Unknown Source)
	at org.apache.derby.jdbc.InternalDriver$LoginCallable.call(Unknown Source)
	at java.util.concurrent.FutureTask.run(FutureTask.java:266)
	at java.util.concurrent.ThreadPoolExecutor.runWorker(ThreadPoolExecutor.java:1149)
	at java.util.concurrent.ThreadPoolExecutor$Worker.run(ThreadPoolExecutor.java:624)
	at java.lang.Thread.run(Thread.java:748)
Caused by: ERROR XJ004: Database 'C:/tmp/database' not found.
	at org.apache.derby.iapi.error.StandardException.newException(Unknown Source)
	at org.apache.derby.impl.jdbc.SQLExceptionFactory.wrapArgsForTransportAcrossDRDA(Unknown Source)
	... 17 more
============= begin nested exception, level (1) ===========
ERROR XJ004: Database 'C:/tmp/database' not found.
	at org.apache.derby.iapi.error.StandardException.newException(Unknown Source)
	at org.apache.derby.impl.jdbc.SQLExceptionFactory.wrapArgsForTransportAcrossDRDA(Unknown Source)
	at org.apache.derby.impl.jdbc.SQLExceptionFactory.getSQLException(Unknown Source)
	at org.apache.derby.impl.jdbc.SQLExceptionFactory.getSQLException(Unknown Source)
	at org.apache.derby.impl.jdbc.Util.generateCsSQLException(Unknown Source)
	at org.apache.derby.impl.jdbc.Util.generateCsSQLException(Unknown Source)
	at org.apache.derby.impl.jdbc.EmbedConnection.newSQLException(Unknown Source)
	at org.apache.derby.impl.jdbc.EmbedConnection.handleDBNotFound(Unknown Source)
	at org.apache.derby.impl.jdbc.EmbedConnection.<init>(Unknown Source)
	at org.apache.derby.jdbc.InternalDriver$1.run(Unknown Source)
	at org.apache.derby.jdbc.InternalDriver$1.run(Unknown Source)
	at java.security.AccessController.doPrivileged(Native Method)
	at org.apache.derby.jdbc.InternalDriver.getNewEmbedConnection(Unknown Source)
	at org.apache.derby.jdbc.InternalDriver$LoginCallable.call(Unknown Source)
	at org.apache.derby.jdbc.InternalDriver$LoginCallable.call(Unknown Source)
	at java.util.concurrent.FutureTask.run(FutureTask.java:266)
	at java.util.concurrent.ThreadPoolExecutor.runWorker(ThreadPoolExecutor.java:1149)
	at java.util.concurrent.ThreadPoolExecutor$Worker.run(ThreadPoolExecutor.java:624)
	at java.lang.Thread.run(Thread.java:748)
============= end nested exception, level (1) ===========
Cleanup action completed
Fri Sep 13 08:43:52 MSK 2019 Thread[Thread-4,5,main] Cleanup action starting
java.sql.SQLException: Database 'C:/tmp/database' not found.
	at org.apache.derby.impl.jdbc.SQLExceptionFactory.getSQLException(Unknown Source)
	at org.apache.derby.impl.jdbc.SQLExceptionFactory.getSQLException(Unknown Source)
	at org.apache.derby.impl.jdbc.Util.generateCsSQLException(Unknown Source)
	at org.apache.derby.impl.jdbc.Util.generateCsSQLException(Unknown Source)
	at org.apache.derby.impl.jdbc.EmbedConnection.newSQLException(Unknown Source)
	at org.apache.derby.impl.jdbc.EmbedConnection.handleDBNotFound(Unknown Source)
	at org.apache.derby.impl.jdbc.EmbedConnection.<init>(Unknown Source)
	at org.apache.derby.jdbc.InternalDriver$1.run(Unknown Source)
	at org.apache.derby.jdbc.InternalDriver$1.run(Unknown Source)
	at java.security.AccessController.doPrivileged(Native Method)
	at org.apache.derby.jdbc.InternalDriver.getNewEmbedConnection(Unknown Source)
	at org.apache.derby.jdbc.InternalDriver$LoginCallable.call(Unknown Source)
	at org.apache.derby.jdbc.InternalDriver$LoginCallable.call(Unknown Source)
	at java.util.concurrent.FutureTask.run(FutureTask.java:266)
	at java.util.concurrent.ThreadPoolExecutor.runWorker(ThreadPoolExecutor.java:1149)
	at java.util.concurrent.ThreadPoolExecutor$Worker.run(ThreadPoolExecutor.java:624)
	at java.lang.Thread.run(Thread.java:748)
Caused by: ERROR XJ004: Database 'C:/tmp/database' not found.
	at org.apache.derby.iapi.error.StandardException.newException(Unknown Source)
	at org.apache.derby.impl.jdbc.SQLExceptionFactory.wrapArgsForTransportAcrossDRDA(Unknown Source)
	... 17 more
============= begin nested exception, level (1) ===========
ERROR XJ004: Database 'C:/tmp/database' not found.
	at org.apache.derby.iapi.error.StandardException.newException(Unknown Source)
	at org.apache.derby.impl.jdbc.SQLExceptionFactory.wrapArgsForTransportAcrossDRDA(Unknown Source)
	at org.apache.derby.impl.jdbc.SQLExceptionFactory.getSQLException(Unknown Source)
	at org.apache.derby.impl.jdbc.SQLExceptionFactory.getSQLException(Unknown Source)
	at org.apache.derby.impl.jdbc.Util.generateCsSQLException(Unknown Source)
	at org.apache.derby.impl.jdbc.Util.generateCsSQLException(Unknown Source)
	at org.apache.derby.impl.jdbc.EmbedConnection.newSQLException(Unknown Source)
	at org.apache.derby.impl.jdbc.EmbedConnection.handleDBNotFound(Unknown Source)
	at org.apache.derby.impl.jdbc.EmbedConnection.<init>(Unknown Source)
	at org.apache.derby.jdbc.InternalDriver$1.run(Unknown Source)
	at org.apache.derby.jdbc.InternalDriver$1.run(Unknown Source)
	at java.security.AccessController.doPrivileged(Native Method)
	at org.apache.derby.jdbc.InternalDriver.getNewEmbedConnection(Unknown Source)
	at org.apache.derby.jdbc.InternalDriver$LoginCallable.call(Unknown Source)
	at org.apache.derby.jdbc.InternalDriver$LoginCallable.call(Unknown Source)
	at java.util.concurrent.FutureTask.run(FutureTask.java:266)
	at java.util.concurrent.ThreadPoolExecutor.runWorker(ThreadPoolExecutor.java:1149)
	at java.util.concurrent.ThreadPoolExecutor$Worker.run(ThreadPoolExecutor.java:624)
	at java.lang.Thread.run(Thread.java:748)
============= end nested exception, level (1) ===========
Cleanup action completed
